<?xml version="1.0" encoding="utf-8"?>
<!-- This URDF was automatically created by SolidWorks to URDF Exporter! Originally created by Stephen Brawner (brawner@gmail.com) 
     Commit Version: 1.5.1-0-g916b5db  Build Version: 1.5.7152.31018
     For more information, please see http://wiki.ros.org/sw_urdf_exporter -->
<robot
  name="ARM_GL_FEASimplified">
  <link
    name="base_link">
    <inertial>
      <origin
        xyz="0.42345 -0.78175 0.39384"
        rpy="0 0 0" />
      <mass
        value="2.0723" />
      <inertia
        ixx="0.26421"
        ixy="6.2094E-17"
        ixz="-2.0386E-16"
        iyy="0.2632"
        iyz="0.00035409"
        izz="0.013402" />
    </inertial>
    <visual>
      <origin
        xyz="0 0 0"
        rpy="0 0 0" />
      <geometry>
        <mesh
          filename="package://ARM_GL_FEASimplified/meshes/base_link.STL" />
      </geometry>
      <material
        name="">
        <color
          rgba="0.89804 0.91765 0.92941 1" />
      </material>
    </visual>
    <collision>
      <origin
        xyz="0 0 0"
        rpy="0 0 0" />
      <geometry>
        <mesh
          filename="package://ARM_GL_FEASimplified/meshes/base_link.STL" />
      </geometry>
    </collision>
  </link>
  <link
    name="linear_link">
    <inertial>
      <origin
        xyz="-0.023566 0.0254 -4.22E-10"
        rpy="0 0 0" />
      <mass
        value="0.3983" />
      <inertia
        ixx="0.00021468"
        ixy="1.1874E-11"
        ixz="-1.1027E-18"
        iyy="0.00092937"
        iyz="-3.5223E-12"
        izz="0.00071736" />
    </inertial>
    <visual>
      <origin
        xyz="0 0 0"
        rpy="0 0 0" />
      <geometry>
        <mesh
          filename="package://ARM_GL_FEASimplified/meshes/linear_link.STL" />
      </geometry>
      <material
        name="">
        <color
          rgba="0.89804 0.91765 0.92941 1" />
      </material>
    </visual>
    <collision>
      <origin
        xyz="0 0 0"
        rpy="0 0 0" />
      <geometry>
        <mesh
          filename="package://ARM_GL_FEASimplified/meshes/linear_link.STL" />
      </geometry>
    </collision>
  </link>
  <joint
    name="linear_joint"
    type="fixed">
    <origin
      xyz="0.42345 -0.78271 0.7034"
      rpy="-1.5708 0 1.5708" />
    <parent
      link="base_link" />
    <child
      link="linear_link" />
    <axis
      xyz="0 0 0" />
    <limit
      lower="0"
      upper="0"
      effort="0"
      velocity="0" />
  </joint>
  <link
    name="shoulder_link">
    <inertial>
      <origin
        xyz="0.0127 -0.0254 0.175"
        rpy="0 0 0" />
      <mass
        value="0.1056" />
      <inertia
        ixx="0.0010841"
        ixy="-6.9978E-16"
        ixz="2.5263E-18"
        iyy="0.0010842"
        iyz="-1.3142E-11"
        izz="2.0059E-05" />
    </inertial>
    <visual>
      <origin
        xyz="0 0 0"
        rpy="0 0 0" />
      <geometry>
        <mesh
          filename="package://ARM_GL_FEASimplified/meshes/shoulder_link.STL" />
      </geometry>
      <material
        name="">
        <color
          rgba="0.79216 0.81961 0.93333 1" />
      </material>
    </visual>
    <collision>
      <origin
        xyz="0 0 0"
        rpy="0 0 0" />
      <geometry>
        <mesh
          filename="package://ARM_GL_FEASimplified/meshes/shoulder_link.STL" />
      </geometry>
    </collision>
  </link>
  <joint
    name="shoulder_joint"
    type="fixed">
    <origin
      xyz="-0.10602 0 0.017518"
      rpy="3.1416 0.23193 0" />
    <parent
      link="linear_link" />
    <child
      link="shoulder_link" />
    <axis
      xyz="0 0 0" />
  </joint>
  <link
    name="elbow_link">
    <inertial>
      <origin
        xyz="-6.6613E-16 -0.0254 0.185"
        rpy="0 0 0" />
      <mass
        value="0.092617" />
      <inertia
        ixx="0.0012632"
        ixy="9.3869E-20"
        ixz="3.8133E-18"
        iyy="0.0012426"
        iyz="-7.0674E-18"
        izz="4.1215E-05" />
    </inertial>
    <visual>
      <origin
        xyz="0 0 0"
        rpy="0 0 0" />
      <geometry>
        <mesh
          filename="package://ARM_GL_FEASimplified/meshes/elbow_link.STL" />
      </geometry>
      <material
        name="">
        <color
          rgba="0.79216 0.81961 0.93333 1" />
      </material>
    </visual>
    <collision>
      <origin
        xyz="0 0 0"
        rpy="0 0 0" />
      <geometry>
        <mesh
          filename="package://ARM_GL_FEASimplified/meshes/elbow_link.STL" />
      </geometry>
    </collision>
  </link>
  <joint
    name="elbow_joint"
    type="continuous">
    <origin
      xyz="0.0127 0 0.335"
      rpy="0 0.58421 0" />
    <parent
      link="shoulder_link" />
    <child
      link="elbow_link" />
    <axis
      xyz="0 1 0" />
  </joint>
</robot>