<?xml version="1.0"?>
<sdf version="1.8">
	<world name="car_world">
		<physics name="1ms" type="ignored">
			<max_step_size>0.001</max_step_size>
			<real_time_factor>1.0</real_time_factor>
		</physics>
		<plugin
			filename="ignition-gazebo-physics-system"
			name="ignition::gazebo::systems::Physics"
		>
		</plugin>
		<plugin
			filename="ignition-gazebo-user-commands-system"
			name="ignition::gazebo::systems::UserCommands">
		</plugin>
		<plugin
			filename="ignition-gazebo-scene-broadcaster-system"
			name="ignition::gazebo::systems::SceneBroadcaster">
		</plugin>
		<plugin filename="libignition-gazebo-imu-system"
			name="ignition::gazebo::systems::Imu">
		</plugin>
		<plugin
			filename="ignition-gazebo-sensors-system"
			name="gz::sim::systems::Sensors">
			<render_engine>ogre</render_engine>
		</plugin>

		<scene>
			<ambient>1.0 1.0 1.0</ambient>
			<background>0.8 0.8 0.8</background>
			<grid>true</grid>
		</scene>

		<gui>

			<!-- 3D scene -->
			<plugin filename="MinimalScene" name="3D View">
				<ignition-gui>
					<title>3D View</title>
					<property type="bool" key="showTitleBar">false</property>
					<property type="string" key="state">docked</property>
				</ignition-gui>

				<engine>ogre2</engine>
				<scene>scene</scene>
				<ambient_light>0.4 0.4 0.4</ambient_light>
				<background_color>0.8 0.8 0.8</background_color>
				<camera_pose>-6 0 6 0 0.5 0</camera_pose>
			</plugin>
			<!-- Plugins that add functionality to the scene -->
			<plugin filename="EntityContextMenuPlugin" name="Entity context menu">
				<ignition-gui>
					<property key="state" type="string">floating</property>
					<property key="width" type="double">5</property>
					<property key="height" type="double">5</property>
					<property key="showTitleBar" type="bool">false</property>
				</ignition-gui>
			</plugin>
			<plugin filename="GzSceneManager" name="Scene Manager">
				<ignition-gui>
					<property key="resizable" type="bool">false</property>
					<property key="width" type="double">5</property>
					<property key="height" type="double">5</property>
					<property key="state" type="string">floating</property>
					<property key="showTitleBar" type="bool">false</property>
				</ignition-gui>
			</plugin>
			<plugin filename="InteractiveViewControl" name="Interactive view control">
				<ignition-gui>
					<property key="resizable" type="bool">false</property>
					<property key="width" type="double">5</property>
					<property key="height" type="double">5</property>
					<property key="state" type="string">floating</property>
					<property key="showTitleBar" type="bool">false</property>
				</ignition-gui>
			</plugin>
			<plugin filename="CameraTracking" name="Camera Tracking">
				<ignition-gui>
					<property key="resizable" type="bool">false</property>
					<property key="width" type="double">5</property>
					<property key="height" type="double">5</property>
					<property key="state" type="string">floating</property>
					<property key="showTitleBar" type="bool">false</property>
				</ignition-gui>
			</plugin>
			<!-- World control -->
			<plugin filename="WorldControl" name="World control">
				<ignition-gui>
					<title>World control</title>
					<property type="bool" key="showTitleBar">false</property>
					<property type="bool" key="resizable">false</property>
					<property type="double" key="height">72</property>
					<property type="double" key="width">121</property>
					<property type="double" key="z">1</property>

					<property type="string" key="state">floating</property>
					<anchors target="3D View">
						<line own="left" target="left" />
						<line own="bottom" target="bottom" />
					</anchors>
				</ignition-gui>

				<play_pause>true</play_pause>
				<step>true</step>
				<start_paused>true</start_paused>
				<use_event>true</use_event>

			</plugin>

			<!-- World statistics -->
			<plugin filename="WorldStats" name="World stats">
				<ignition-gui>
					<title>World stats</title>
					<property type="bool" key="showTitleBar">false</property>
					<property type="bool" key="resizable">false</property>
					<property type="double" key="height">110</property>
					<property type="double" key="width">290</property>
					<property type="double" key="z">1</property>

					<property type="string" key="state">floating</property>
					<anchors target="3D View">
						<line own="right" target="right" />
						<line own="bottom" target="bottom" />
					</anchors>
				</ignition-gui>

				<sim_time>true</sim_time>
				<real_time>true</real_time>
				<real_time_factor>true</real_time_factor>
				<iterations>true</iterations>
			</plugin>

			<plugin filename="ImageDisplay" name="Image Display">
				<ignition-gui>
					<property key="state" type="string">docked</property>
				</ignition-gui>
			</plugin>

			<!-- Inspector -->
			<plugin filename="ComponentInspector" name="Component inspector">
				<ignition-gui>
					<property type="string" key="state">docked</property>
				</ignition-gui>
			</plugin>

			<!-- Entity tree -->
			<plugin filename="EntityTree" name="Entity tree">
				<ignition-gui>
					<property type="string" key="state">docked</property>
				</ignition-gui>
			</plugin>

		</gui>

		<light type="directional" name="sun">
			<cast_shadows>true</cast_shadows>
			<pose>0 0 10 0 0 0</pose>
			<diffuse>0.8 0.8 0.8 1</diffuse>
			<specular>0.2 0.2 0.2 1</specular>
			<attenuation>
				<range>1000</range>
				<constant>0.9</constant>
				<linear>0.01</linear>
				<quadratic>0.001</quadratic>
			</attenuation>
			<direction>-0.5 0.1 -0.9</direction>
		</light>

		<model name="ground_plane">
			<static>true</static>
			<link name="link">
				<collision name="collision">
					<geometry>
						<plane>
							<normal>0 0 1</normal>
						</plane>
					</geometry>
				</collision>
				<visual name="visual">
					<geometry>
						<plane>
							<normal>0 0 1</normal>
							<size>100 100</size>
						</plane>
					</geometry>
					<material>
						<ambient>0.8 0.8 0.8 1</ambient>
						<diffuse>0.8 0.8 0.8 1</diffuse>
						<specular>0.8 0.8 0.8 1</specular>
					</material>
				</visual>
			</link>
		</model>

		<include>
			<pose>3 1 0 0.0 0.0 0.0</pose>
			<uri>
				https://fuel.gazebosim.org/1.0/OpenRobotics/models/Construction Cone
			</uri>
		</include>

		<include>
			<pose>6 -2 0 0.0 0.0 0.0</pose>
			<uri>
				https://fuel.gazebosim.org/1.0/SegQx/models/DRC Practice: Orange Jersey Barrier
			</uri>
		</include>

		<model name="wall">
			<static>true</static>
			<pose>10 0 0 0 0 0</pose><!--pose
			relative to the world-->
			<link name="box">
				<pose />
				<visual name="visual">
					<geometry>
						<box>
							<size>0.5 10.0 2.0</size>
						</box>
					</geometry>
					<!--let's
					add color to our link-->
					<material>
						<ambient>0.0 1.0 1.0 1</ambient>
						<diffuse>0.0 1.0 1.0 1</diffuse>
						<specular>0.0 1.0 1.0 1</specular>
					</material>
				</visual>
				<collision name="collision">
					<geometry>
						<box>
							<size>0.5 10.0 2.0</size>
						</box>
					</geometry>
				</collision>
			</link>
		</model>

		<model name="vehicle_blue" canonical_link="chassis">
			<pose relative_to="world">0 0 0 0 0 0</pose>

			<link name="chassis">
				<pose relative_to="__model__">0.5 0 0.4 0 0 0</pose>
				<inertial>
					<!-- inertial properties of the link mass, inertia matix -->
					<mass>1.14395</mass>
					<inertia>
						<ixx>0.095329</ixx>
						<ixy>0</ixy>
						<ixz>0</ixz>
						<iyy>0.381317</iyy>
						<iyz>0</iyz>
						<izz>0.476646</izz>
					</inertia>
				</inertial>
				<visual name="visual">
					<geometry>
						<box>
							<size>2.0 1.0 0.5</size>
						</box>
					</geometry>
					<material>
						<ambient>0.0 0.0 1.0 1</ambient>
						<diffuse>0.0 0.0 1.0 1</diffuse>
						<specular>0.0 0.0 1.0 1</specular>
					</material>
				</visual>
				<collision name="collision">
					<geometry>
						<box>
							<size>2.0 1.0 0.5</size>
						</box>
					</geometry>
				</collision>

				<sensor name="imu_sensor" type="imu">
					<always_on>1</always_on>
					<update_rate>1</update_rate>
					<visualize>true</visualize>
					<topic>imu</topic>
				</sensor>
			</link>

			<link name="camera">
				<pose relative_to="chassis">1 0 0.2 0 0 0</pose>
				<inertial>
					<mass>0.1</mass>
					<inertia>
						<ixx>0.000166667</ixx>
						<iyy>0.000166667</iyy>
						<izz>0.000166667</izz>
					</inertia>
				</inertial>
				<collision name="collision">
					<geometry>
						<box>
							<size>0.1 0.1 0.1</size>
						</box>
					</geometry>
				</collision>
				<visual name="visual">
					<geometry>
						<box>
							<size>0.1 0.1 0.1</size>
						</box>
					</geometry>
				</visual>
				<sensor name="camera" type="camera">
					<camera>
						<horizontal_fov>1.047</horizontal_fov>
						<image>
							<width>320</width>
							<height>240</height>
						</image>
						<clip>
							<near>0.1</near>
							<far>100</far>
						</clip>
					</camera>
					<always_on>1</always_on>
					<update_rate>30</update_rate>
					<visualize>true</visualize>
					<topic>camera</topic>
				</sensor>
			</link>

			<link name="left_wheel">
				<pose relative_to="chassis">-0.5 0.6 0 -1.5707 0 0</pose>
				<inertial>
					<mass>1</mass>
					<inertia>
						<ixx>0.043333</ixx>
						<ixy>0</ixy>
						<ixz>0</ixz>
						<iyy>0.043333</iyy>
						<iyz>0</iyz>
						<izz>0.08</izz>
					</inertia>
				</inertial>
				<visual name="visual">
					<geometry>
						<cylinder>
							<radius>0.4</radius>
							<length>0.2</length>
						</cylinder>
					</geometry>
					<material>
						<ambient>1.0 0.0 0.0 1</ambient>
						<diffuse>1.0 0.0 0.0 1</diffuse>
						<specular>1.0 0.0 0.0 1</specular>
					</material>
				</visual>
				<collision name="collision">
					<geometry>
						<cylinder>
							<radius>0.4</radius>
							<length>0.2</length>
						</cylinder>
					</geometry>
				</collision>
			</link>

			<link name="right_wheel">
				<pose relative_to="chassis">-0.5 -0.6 0 -1.5707 0 0</pose>
				<!-- angles are in radian -->
				<inertial>
					<mass>1</mass>
					<inertia>
						<ixx>0.043333</ixx>
						<ixy>0</ixy>
						<ixz>0</ixz>
						<iyy>0.043333</iyy>
						<iyz>0</iyz>
						<izz>0.08</izz>
					</inertia>
				</inertial>
				<visual name="visual">
					<geometry>
						<cylinder>
							<radius>0.4</radius>
							<length>0.2</length>
						</cylinder>
					</geometry>
					<material>
						<ambient>1.0 0.0 0.0 1</ambient>
						<diffuse>1.0 0.0 0.0 1</diffuse>
						<specular>1.0 0.0 0.0 1</specular>
					</material>
				</visual>
				<collision name="collision">
					<geometry>
						<cylinder>
							<radius>0.4</radius>
							<length>0.2</length>
						</cylinder>
					</geometry>
				</collision>
			</link>
			<!-- abritrary frame -->
			<frame name="caster_frame" attached_to="chassis">
				<pose>0.8 0 -0.2 0 0 0</pose>
			</frame>
			<!-- caster wheel -->
			<link name="caster">
				<pose relative_to="caster_frame" />
				<inertial>
					<mass>1</mass>
					<inertia>
						<ixx>0.016</ixx>
						<ixy>0</ixy>
						<ixz>0</ixz>
						<iyy>0.016</iyy>
						<iyz>0</iyz>
						<izz>0.016</izz>
					</inertia>
				</inertial>
				<visual name="visual">
					<geometry>
						<sphere>
							<radius>0.2</radius>
						</sphere>
					</geometry>
					<material>
						<ambient>0.0 1 0.0 1</ambient>
						<diffuse>0.0 1 0.0 1</diffuse>
						<specular>0.0 1 0.0 1</specular>
					</material>
				</visual>
				<collision name="collision">
					<geometry>
						<sphere>
							<radius>0.2</radius>
						</sphere>
					</geometry>
				</collision>
			</link>
			<!-- left wheel joint -->
			<joint name="left_wheel_joint" type="revolute">
				<pose relative_to="left_wheel" />
				<parent>chassis</parent>
				<child>left_wheel</child>
				<axis>
					<xyz expressed_in="__model__">0 1 0</xyz>
					<limit>
						<lower>-1.79769e+308</lower> <!-- negative infinity -->
						<upper>1.79769e+308</upper> <!-- positive infinity -->
					</limit>
				</axis>
			</joint>
			<!-- right wheel joint -->
			<joint name="right_wheel_joint" type="revolute">
				<pose relative_to="right_wheel" />
				<parent>chassis</parent>
				<child>right_wheel</child>
				<axis>
					<xyz expressed_in="__model__">0 1 0</xyz>
					<limit>
						<lower>-1.79769e+308</lower> <!-- negative infinity -->
						<upper>1.79769e+308</upper> <!-- positive infinity -->
					</limit>
				</axis>
			</joint>
			<!-- caster wheel joint -->
			<!-- pose defult value is the child -->
			<joint name="caster_wheel" type="ball">
				<parent>chassis</parent>
				<child>caster</child>
			</joint>
			<!-- Diff drive -->
			<plugin
				filename="libignition-gazebo-diff-drive-system"
				name="ignition::gazebo::systems::DiffDrive">
				<left_joint>left_wheel_joint</left_joint>
				<right_joint>right_wheel_joint</right_joint>
				<wheel_separation>1.2</wheel_separation>
				<wheel_radius>0.4</wheel_radius>
				<odom_publish_frequency>1</odom_publish_frequency>
				<topic>cmd_vel</topic>
			</plugin>
		</model>
		<!-- Moving robot with keyboard arrows -->
		<!-- Moving Forward-->
		<plugin filename="libignition-gazebo-triggered-publisher-system.so"
			name="ignition::gazebo::systems::TriggeredPublisher">
			<input type="ignition.msgs.Int32" topic="/keyboard/keypress">
				<match field="data">16777235</match>
			</input>
			<output type="ignition.msgs.Twist" topic="/cmd_vel">
				linear: {x: 0.5}, angular: {z: 0.0}
			</output>
		</plugin>
		<!-- Moving Backward-->
		<plugin filename="libignition-gazebo-triggered-publisher-system.so"
			name="ignition::gazebo::systems::TriggeredPublisher">
			<input type="ignition.msgs.Int32" topic="/keyboard/keypress">
				<match field="data">16777237</match>
			</input>
			<output type="ignition.msgs.Twist" topic="/cmd_vel">
				linear: {x: -0.5}, angular: {z: 0.0}
			</output>
		</plugin>
		<!-- Rotating right-->
		<plugin filename="libignition-gazebo-triggered-publisher-system.so"
			name="ignition::gazebo::systems::TriggeredPublisher">
			<input type="ignition.msgs.Int32" topic="/keyboard/keypress">
				<match field="data">16777236</match>
			</input>
			<output type="ignition.msgs.Twist" topic="/cmd_vel">
				linear: {x: 0.0}, angular: {z: -0.5}
			</output>
		</plugin>
		<!-- Rotating left -->
		<plugin filename="libignition-gazebo-triggered-publisher-system.so"
			name="ignition::gazebo::systems::TriggeredPublisher">
			<input type="ignition.msgs.Int32" topic="/keyboard/keypress">
				<match field="data">16777234</match>
			</input>
			<output type="ignition.msgs.Twist" topic="/cmd_vel">
				linear: {x: 0.0}, angular: {z: 0.5}
			</output>
		</plugin>

	</world>
</sdf>