<?xml version="1.0" encoding="utf-8" ?>
<!-- This URDF was automatically created by SolidWorks to URDF Exporter! Originally created by Stephen Brawner (brawner@gmail.com) 
     Commit Version: 1.6.0-1-g15f4949  Build Version: 1.6.7594.29634
     For more information, please see http://wiki.ros.org/sw_urdf_exporter -->
<robot name="brc_arm_description">
<!-- Need the world joint to fix the robot down (user generated) -->
    <link name="world" />
    <joint name="fixed" type="fixed">
        <parent link="world" />
        <child link="base_link" />
    </joint>
<!-- end user generated -->
    <link name="base_link">
        
<inertial>
            <origin xyz="-2.12897969231804E-17 -0.00436320369577433 0.380907780979827" rpy="0 0 0" />
            <mass value="5.45066325397829" />
            <inertia ixx="0.585603075889073" ixy="-2.90028918727806E-18" ixz="5.04131064644661E-19" iyy="0.580821568393074" iyz="0.00342685216919008" izz="0.0231148604746449" />
        </inertial>

        <visual>
            <origin xyz="0 0 0" rpy="0 0 0" />
            <geometry>
                <mesh filename="package://brc_arm_description/meshes/base_link.STL" />
            </geometry>
            <material name="">
                <color rgba="0.792156862745098 0.819607843137255 0.933333333333333 1" />
            </material>
        </visual>
        <collision>
            <origin xyz="0 0 0" rpy="0 0 0" />
            <geometry>
                <mesh filename="package://brc_arm_description/meshes/base_link.STL" />
            </geometry>
        </collision>
    </link>
    <link name="carriage">
        
<inertial>
            <origin xyz="2.06924078782665E-18 0.0306198670554826 0.0539046334093021" rpy="0 0 0" />
            <mass value="0.447720870142158" />
            <inertia ixx="0.00109900282993972" ixy="8.14695699840894E-21" ixz="3.79103984897485E-21" iyy="0.00119322484755841" iyz="3.2818418789354E-20" izz="0.000280772380177922" />
        </inertial>

        <visual>
            <origin xyz="0 0 0" rpy="0 0 0" />
            <geometry>
                <mesh filename="package://brc_arm_description/meshes/carriage.STL" />
            </geometry>
            <material name="">
                <color rgba="0.792156862745098 0.819607843137255 0.933333333333333 1" />
            </material>
        </visual>
        <collision>
            <origin xyz="0 0 0" rpy="0 0 0" />
            <geometry>
                <mesh filename="package://brc_arm_description/meshes/carriage.STL" />
            </geometry>
        </collision>
    </link>
    <joint name="carriageJ" type="prismatic">
        <origin xyz="0 0 0.065" rpy="1.5708 0 0" />
        <parent link="base_link" />
        <child link="carriage" />
        <axis xyz="0 1 0" />
        <limit lower="0" upper="0.885" effort="0" velocity="0" />
    </joint>
    <link name="midarm1">
        
<inertial>
            <origin xyz="-0.203557861047764 0.0296868806428557 -0.0233639836713498" rpy="0 0 0" />
            <mass value="0.836203235137727" />
            <inertia ixx="0.00151945911351229" ixy="-0.000102923359495151" ixz="0.000240522861339408" iyy="0.00702698610521793" iyz="-9.31764631877637E-05" izz="0.00718374226941061" />
        </inertial>

        <visual>
            <origin xyz="0 0 0" rpy="0 0 0" />
            <geometry>
                <mesh filename="package://brc_arm_description/meshes/midarm1.STL" />
            </geometry>
            <material name="">
                <color rgba="0.792156862745098 0.819607843137255 0.933333333333333 1" />
            </material>
        </visual>
        <collision>
            <origin xyz="0 0 0" rpy="0 0 0" />
            <geometry>
                <mesh filename="package://brc_arm_description/meshes/midarm1.STL" />
            </geometry>
        </collision>
    </link>
    <joint name="midarm1J" type="continuous">
        <origin xyz="0 0 0.1" rpy="0 1.5708 0" />
        <parent link="carriage" />
        <child link="midarm1" />
        <axis xyz="0 1 0" />
        <limit lower="0" upper="6.283" effort="0" velocity="0" />
    </joint>
    <link name="midarm2">
        
<inertial>
            <origin xyz="0.0437798591057958 -0.0263016163556158 7.92303168854812E-19" rpy="0 0 0" />
            <mass value="0.0646775902886999" />
            <inertia ixx="2.37281453591281E-05" ixy="1.49350689133809E-06" ixz="2.48625409012808E-21" iyy="7.79483607629912E-05" iyz="2.15540460356491E-21" izz="9.13128623062532E-05" />
        </inertial>

        <visual>
            <origin xyz="0 0 0" rpy="0 0 0" />
            <geometry>
                <mesh filename="package://brc_arm_description/meshes/midarm2.STL" />
            </geometry>
            <material name="">
                <color rgba="0.792156862745098 0.819607843137255 0.933333333333333 1" />
            </material>
        </visual>
        <collision>
            <origin xyz="0 0 0" rpy="0 0 0" />
            <geometry>
                <mesh filename="package://brc_arm_description/meshes/midarm2.STL" />
            </geometry>
        </collision>
    </link>
    <joint name="midarm2J" type="continuous">
        <origin xyz="-0.35 0 0" rpy="0 0 -3.1416" />
        <parent link="midarm1" />
        <child link="midarm2" />
        <axis xyz="0 1 0" />
        <limit lower="0" upper="6.283" effort="0" velocity="0" />
    </joint>
    <link name="wrist1">
        
<inertial>
            <origin xyz="0.0903131624724215 -0.000992457227295296 -0.0267491411281867" rpy="0 0 0" />
            <mass value="0.419666572951628" />
            <inertia ixx="0.000442065921287954" ixy="-2.7070998496465E-06" ixz="0.000100949564251368" iyy="0.00153234612957666" iyz="4.94992809779878E-05" izz="0.00143304792270374" />
        </inertial>

        <visual>
            <origin xyz="0 0 0" rpy="0 0 0" />
            <geometry>
                <mesh filename="package://brc_arm_description/meshes/wrist1.STL" />
            </geometry>
            <material name="">
                <color rgba="0.792156862745098 0.819607843137255 0.933333333333333 1" />
            </material>
        </visual>
        <collision>
            <origin xyz="0 0 0" rpy="0 0 0" />
            <geometry>
                <mesh filename="package://brc_arm_description/meshes/wrist1.STL" />
            </geometry>
        </collision>
    </link>
    <joint name="wrist1J" type="continuous">
        <origin xyz="0.08 -0.025 0" rpy="0 0 0" />
        <parent link="midarm2" />
        <child link="wrist1" />
        <axis xyz="0 0 1" />
        <limit lower="0" upper="6.283" effort="0" velocity="0" />
    </joint>
    <link name="wrist2">
        
<inertial>
            <origin xyz="0.0437675106277474 0.0238805676834205 0.00653583627389278" rpy="0 0 0" />
            <mass value="0.129512939632169" />
            <inertia ixx="0.000129578871359291" ixy="2.78573241574099E-06" ixz="-2.6631490528225E-06" iyy="8.51895226343727E-05" iyz="-9.11411396579337E-07" izz="0.000185624075448265" />
        </inertial>

        <visual>
            <origin xyz="0 0 0" rpy="0 0 0" />
            <geometry>
                <mesh filename="package://brc_arm_description/meshes/wrist2.STL" />
            </geometry>
            <material name="">
                <color rgba="0.792156862745098 0.819607843137255 0.933333333333333 1" />
            </material>
        </visual>
        <collision>
            <origin xyz="0 0 0" rpy="0 0 0" />
            <geometry>
                <mesh filename="package://brc_arm_description/meshes/wrist2.STL" />
            </geometry>
        </collision>
    </link>
    <joint name="wrist2J" type="continuous">
        <origin xyz="0.225 0 0" rpy="-3.1416 0 0" />
        <parent link="wrist1" />
        <child link="wrist2" />
        <axis xyz="0 1 0" />
        <limit lower="0" upper="6.283" effort="0" velocity="0" />
    </joint>
    <link name="EEbase">
        
<inertial>
            <origin xyz="1.84556577658727E-18 0.00561986705548088 -0.0378694927465377" rpy="0 0 0" />
            <mass value="0.0926044760959501" />
            <inertia ixx="4.81318826783347E-05" ixy="-5.07498887549915E-21" ixz="-7.07219912323867E-21" iyy="7.32482359165229E-05" iyz="2.29632639397096E-20" izz="3.29932559448167E-05" />
        </inertial>

        <visual>
            <origin xyz="0 0 0" rpy="0 0 0" />
            <geometry>
                <mesh filename="package://brc_arm_description/meshes/EEbase.STL" />
            </geometry>
            <material name="">
                <color rgba="0.792156862745098 0.819607843137255 0.933333333333333 1" />
            </material>
        </visual>
        <collision>
            <origin xyz="0 0 0" rpy="0 0 0" />
            <geometry>
                <mesh filename="package://brc_arm_description/meshes/EEbase.STL" />
            </geometry>
        </collision>
    </link>
    <joint name="EEbaseJ" type="continuous">
        <origin xyz="0.095 0 0" rpy="0 -1.5708 0" />
        <parent link="wrist2" />
        <child link="EEbase" />
        <axis xyz="0 0 1" />
        <limit lower="0" upper="0" effort="0" velocity="0" />
    </joint>
    <link name="RLink1">
        
<inertial>
            <origin xyz="0.0400000000000001 0.00311986705547995 -2.22044604925031E-16" rpy="0 0 0" />
            <mass value="0.00668722339297274" />
            <inertia ixx="1.38550163626321E-07" ixy="-2.42585682543688E-22" ixz="1.3178569943765E-20" iyy="4.66129432520501E-06" iyz="6.64806213898613E-23" izz="4.55060759238274E-06" />
        </inertial>

        <visual>
            <origin xyz="0 0 0" rpy="0 0 0" />
            <geometry>
                <mesh filename="package://brc_arm_description/meshes/RLink1.STL" />
            </geometry>
            <material name="">
                <color rgba="0.792156862745098 0.819607843137255 0.933333333333333 1" />
            </material>
        </visual>
        <collision>
            <origin xyz="0 0 0" rpy="0 0 0" />
            <geometry>
                <mesh filename="package://brc_arm_description/meshes/RLink1.STL" />
            </geometry>
        </collision>
    </link>
    <joint name="RLink1J" type="revolute">
        <origin xyz="0.024 -0.011 -0.019185" rpy="0 0 0" />
        <parent link="EEbase" />
        <child link="RLink1" />
        <axis xyz="0 1 0" />
        <limit lower="0" upper="6.283" effort="0" velocity="0" />
    </joint>
    <link name="RFinger">
        
<inertial>
            <origin xyz="0.0174831476155701 0.0707338411471631 -0.0166198670554799" rpy="0 0 0" />
            <mass value="0.052748844949343" />
            <inertia ixx="9.60936833531592E-05" ixy="-3.36352218446776E-05" ixz="-3.82300941081563E-20" iyy="1.6892750542267E-05" iyz="-1.04902923842264E-19" izz="0.000108731360402846" />
        </inertial>

        <visual>
            <origin xyz="0 0 0" rpy="0 0 0" />
            <geometry>
                <mesh filename="package://brc_arm_description/meshes/RFinger.STL" />
            </geometry>
            <material name="">
                <color rgba="1 0.717647058823529 0.819607843137255 1" />
            </material>
        </visual>
        <collision>
            <origin xyz="0 0 0" rpy="0 0 0" />
            <geometry>
                <mesh filename="package://brc_arm_description/meshes/RFinger.STL" />
            </geometry>
        </collision>
    </link>
    <joint name="RFingerJ" type="revolute">
        <origin xyz="0.0800000000000002 0 0" rpy="-1.5707963267949 0 3.14159265358979" />
        <parent link="RLink1" />
        <child link="RFinger" />
        <axis xyz="0 0 1" />
        <limit lower="0" upper="0" effort="0" velocity="0" />
        <mimic joint="RLink1J" multiplier="-1" offset="0" />
    </joint>
    <link name="LLink1">
        
<inertial>
            <origin xyz="-0.0400000000000047 0.00311986705548005 6.66133814775094E-16" rpy="0 0 0" />
            <mass value="0.00668722339297275" />
            <inertia ixx="1.38550163626322E-07" ixy="4.1761357507031E-23" ixz="7.26972165963073E-22" iyy="4.66129432520502E-06" iyz="9.1233885874819E-23" izz="4.55060759238275E-06" />
        </inertial>

        <visual>
            <origin xyz="0 0 0" rpy="0 0 0" />
            <geometry>
                <mesh filename="package://brc_arm_description/meshes/LLink1.STL" />
            </geometry>
            <material name="">
                <color rgba="0.792156862745098 0.819607843137255 0.933333333333333 1" />
            </material>
        </visual>
        <collision>
            <origin xyz="0 0 0" rpy="0 0 0" />
            <geometry>
                <mesh filename="package://brc_arm_description/meshes/LLink1.STL" />
            </geometry>
        </collision>
    </link>
    <joint name="LLink1J" type="revolute">
        <origin xyz="-0.024 -0.011 -0.019185" rpy="0 0 0" />
        <parent link="EEbase" />
        <child link="LLink1" />
        <axis xyz="0 1 0" />
        <limit lower="0" upper="0" effort="0" velocity="0" />
        <mimic joint="RLink1J" multiplier="-1" offset="0" />
    </joint>
    <link name="LFinger">
        
<inertial>
            <origin xyz="0.0174831476155641 0.0707338411471632 0.0166198670554801" rpy="0 0 0" />
            <mass value="0.052748844949343" />
            <inertia ixx="9.60936833531593E-05" ixy="-3.36352218446776E-05" ixz="1.5620470398883E-20" iyy="1.6892750542267E-05" iyz="3.88095453653697E-20" izz="0.000108731360402846" />
        </inertial>

        <visual>
            <origin xyz="0 0 0" rpy="0 0 0" />
            <geometry>
                <mesh filename="package://brc_arm_description/meshes/LFinger.STL" />
            </geometry>
            <material name="">
                <color rgba="1 0.717647058823529 0.819607843137255 1" />
            </material>
        </visual>
        <collision>
            <origin xyz="0 0 0" rpy="0 0 0" />
            <geometry>
                <mesh filename="package://brc_arm_description/meshes/LFinger.STL" />
            </geometry>
        </collision>
    </link>
    <joint name="LFingerJ" type="revolute">
        <origin xyz="-0.079999999999994 0 0" rpy="-1.5707963267949 0 0" />
        <parent link="LLink1" />
        <child link="LFinger" />
        <axis xyz="0 0 1" />
        <limit lower="0" upper="0" effort="0" velocity="0" />
        <mimic joint="LLink1J" multiplier="-1" offset="0" />
    </joint>
    
<transmission name="trans_carriageJ">
        <type>transmission_interface/SimpleTransmission</type>
        <joint name="carriageJ">
            <hardwareInterface>hardware_interface/PositionJointInterface</hardwareInterface>
        </joint>
        <actuator name="carriageJ_motor">
            <hardwareInterface>hardware_interface/PositionJointInterface</hardwareInterface>
            <mechanicalReduction>1</mechanicalReduction>
        </actuator>
    </transmission>
    <transmission name="trans_midarm1J">
        <type>transmission_interface/SimpleTransmission</type>
        <joint name="midarm1J">
            <hardwareInterface>hardware_interface/PositionJointInterface</hardwareInterface>
        </joint>
        <actuator name="midarm1J_motor">
            <hardwareInterface>hardware_interface/PositionJointInterface</hardwareInterface>
            <mechanicalReduction>1</mechanicalReduction>
        </actuator>
    </transmission>
    <transmission name="trans_midarm2J">
        <type>transmission_interface/SimpleTransmission</type>
        <joint name="midarm2J">
            <hardwareInterface>hardware_interface/PositionJointInterface</hardwareInterface>
        </joint>
        <actuator name="midarm2J_motor">
            <hardwareInterface>hardware_interface/PositionJointInterface</hardwareInterface>
            <mechanicalReduction>1</mechanicalReduction>
        </actuator>
    </transmission>
    <transmission name="trans_wrist1J">
        <type>transmission_interface/SimpleTransmission</type>
        <joint name="wrist1J">
            <hardwareInterface>hardware_interface/PositionJointInterface</hardwareInterface>
        </joint>
        <actuator name="wrist1J_motor">
            <hardwareInterface>hardware_interface/PositionJointInterface</hardwareInterface>
            <mechanicalReduction>1</mechanicalReduction>
        </actuator>
    </transmission>
    <transmission name="trans_wrist2J">
        <type>transmission_interface/SimpleTransmission</type>
        <joint name="wrist2J">
            <hardwareInterface>hardware_interface/PositionJointInterface</hardwareInterface>
        </joint>
        <actuator name="wrist2J_motor">
            <hardwareInterface>hardware_interface/PositionJointInterface</hardwareInterface>
            <mechanicalReduction>1</mechanicalReduction>
        </actuator>
    </transmission>
    <transmission name="trans_EEbaseJ">
        <type>transmission_interface/SimpleTransmission</type>
        <joint name="EEbaseJ">
            <hardwareInterface>hardware_interface/PositionJointInterface</hardwareInterface>
        </joint>
        <actuator name="EEbaseJ_motor">
            <hardwareInterface>hardware_interface/PositionJointInterface</hardwareInterface>
            <mechanicalReduction>1</mechanicalReduction>
        </actuator>
    </transmission>
    <transmission name="trans_RLink1J">
        <type>transmission_interface/SimpleTransmission</type>
        <joint name="RLink1J">
            <hardwareInterface>hardware_interface/PositionJointInterface</hardwareInterface>
        </joint>
        <actuator name="RLink1J_motor">
            <hardwareInterface>hardware_interface/PositionJointInterface</hardwareInterface>
            <mechanicalReduction>1</mechanicalReduction>
        </actuator>
    </transmission>
    <transmission name="trans_RFingerJ">
        <type>transmission_interface/SimpleTransmission</type>
        <joint name="RFingerJ">
            <hardwareInterface>hardware_interface/EffortJointInterface</hardwareInterface>
        </joint>
        <actuator name="RFingerJ_motor">
            <hardwareInterface>hardware_interface/EffortJointInterface</hardwareInterface>
            <mechanicalReduction>1</mechanicalReduction>
        </actuator>
    </transmission>
    <transmission name="trans_LLink1J">
        <type>transmission_interface/SimpleTransmission</type>
        <joint name="LLink1J">
            <hardwareInterface>hardware_interface/EffortJointInterface</hardwareInterface>
        </joint>
        <actuator name="LLink1J_motor">
            <hardwareInterface>hardware_interface/EffortJointInterface</hardwareInterface>
            <mechanicalReduction>1</mechanicalReduction>
        </actuator>
    </transmission>
    <transmission name="trans_LFingerJ">
        <type>transmission_interface/SimpleTransmission</type>
        <joint name="LFingerJ">
            <hardwareInterface>hardware_interface/EffortJointInterface</hardwareInterface>
        </joint>
        <actuator name="LFingerJ_motor">
            <hardwareInterface>hardware_interface/EffortJointInterface</hardwareInterface>
            <mechanicalReduction>1</mechanicalReduction>
        </actuator>
    </transmission>
    <gazebo>
        <plugin name="gazebo_ros_control" filename="libgazebo_ros_control.so">
            <robotNamespace>/</robotNamespace>
        </plugin>
    </gazebo>
</robot>